<<<<<<< HEAD
2025-07-15 15:53:58,095 INFO: Microblog startup [in C:\Users\PROGRAMADOR\documentos\blog\blog_1\app\__init__.py:43]
2025-07-15 15:54:00,089 ERROR: Exception on / [GET] [in C:\Users\PROGRAMADOR\AppData\Local\Programs\Python\Python312\Lib\site-packages\flask\app.py:838]
Traceback (most recent call last):
  File "C:\Users\PROGRAMADOR\AppData\Local\Programs\Python\Python312\Lib\site-packages\flask\app.py", line 1473, in wsgi_app
    response = self.full_dispatch_request()
               ^^^^^^^^^^^^^^^^^^^^^^^^^^^^
  File "C:\Users\PROGRAMADOR\AppData\Local\Programs\Python\Python312\Lib\site-packages\flask\app.py", line 882, in full_dispatch_request
    rv = self.handle_user_exception(e)
         ^^^^^^^^^^^^^^^^^^^^^^^^^^^^^
  File "C:\Users\PROGRAMADOR\AppData\Local\Programs\Python\Python312\Lib\site-packages\flask\app.py", line 880, in full_dispatch_request
    rv = self.dispatch_request()
         ^^^^^^^^^^^^^^^^^^^^^^^
  File "C:\Users\PROGRAMADOR\AppData\Local\Programs\Python\Python312\Lib\site-packages\flask\app.py", line 865, in dispatch_request
    return self.ensure_sync(self.view_functions[rule.endpoint])(**view_args)  # type: ignore[no-any-return]
           ^^^^^^^^^^^^^^^^^^^^^^^^^^^^^^^^^^^^^^^^^^^^^^^^^^^^^^^^^^^^^^^^^
  File "C:\Users\PROGRAMADOR\AppData\Local\Programs\Python\Python312\Lib\site-packages\flask_login\utils.py", line 285, in decorated_view
    return current_app.login_manager.unauthorized()
           ^^^^^^^^^^^^^^^^^^^^^^^^^^^^^^^^^^^^^^^^
  File "C:\Users\PROGRAMADOR\AppData\Local\Programs\Python\Python312\Lib\site-packages\flask_login\login_manager.py", line 187, in unauthorized
    flash(self.login_message, category=self.login_message_category)
  File "C:\Users\PROGRAMADOR\AppData\Local\Programs\Python\Python312\Lib\site-packages\flask\helpers.py", line 323, in flash
    session["_flashes"] = flashes
    ~~~~~~~^^^^^^^^^^^^
  File "C:\Users\PROGRAMADOR\AppData\Local\Programs\Python\Python312\Lib\site-packages\flask\sessions.py", line 102, in _fail
    raise RuntimeError(
RuntimeError: The session is unavailable because no secret key was set.  Set the secret_key on the application to something unique and secret.
2025-07-15 15:54:03,844 ERROR: Exception on / [GET] [in C:\Users\PROGRAMADOR\AppData\Local\Programs\Python\Python312\Lib\site-packages\flask\app.py:838]
Traceback (most recent call last):
  File "C:\Users\PROGRAMADOR\AppData\Local\Programs\Python\Python312\Lib\site-packages\flask\app.py", line 1473, in wsgi_app
    response = self.full_dispatch_request()
               ^^^^^^^^^^^^^^^^^^^^^^^^^^^^
  File "C:\Users\PROGRAMADOR\AppData\Local\Programs\Python\Python312\Lib\site-packages\flask\app.py", line 882, in full_dispatch_request
    rv = self.handle_user_exception(e)
         ^^^^^^^^^^^^^^^^^^^^^^^^^^^^^
  File "C:\Users\PROGRAMADOR\AppData\Local\Programs\Python\Python312\Lib\site-packages\flask\app.py", line 880, in full_dispatch_request
    rv = self.dispatch_request()
         ^^^^^^^^^^^^^^^^^^^^^^^
  File "C:\Users\PROGRAMADOR\AppData\Local\Programs\Python\Python312\Lib\site-packages\flask\app.py", line 865, in dispatch_request
    return self.ensure_sync(self.view_functions[rule.endpoint])(**view_args)  # type: ignore[no-any-return]
           ^^^^^^^^^^^^^^^^^^^^^^^^^^^^^^^^^^^^^^^^^^^^^^^^^^^^^^^^^^^^^^^^^
  File "C:\Users\PROGRAMADOR\AppData\Local\Programs\Python\Python312\Lib\site-packages\flask_login\utils.py", line 285, in decorated_view
    return current_app.login_manager.unauthorized()
           ^^^^^^^^^^^^^^^^^^^^^^^^^^^^^^^^^^^^^^^^
  File "C:\Users\PROGRAMADOR\AppData\Local\Programs\Python\Python312\Lib\site-packages\flask_login\login_manager.py", line 187, in unauthorized
    flash(self.login_message, category=self.login_message_category)
  File "C:\Users\PROGRAMADOR\AppData\Local\Programs\Python\Python312\Lib\site-packages\flask\helpers.py", line 323, in flash
    session["_flashes"] = flashes
    ~~~~~~~^^^^^^^^^^^^
  File "C:\Users\PROGRAMADOR\AppData\Local\Programs\Python\Python312\Lib\site-packages\flask\sessions.py", line 102, in _fail
    raise RuntimeError(
RuntimeError: The session is unavailable because no secret key was set.  Set the secret_key on the application to something unique and secret.
2025-07-15 15:54:07,894 ERROR: Exception on /user/hol [GET] [in C:\Users\PROGRAMADOR\AppData\Local\Programs\Python\Python312\Lib\site-packages\flask\app.py:838]
Traceback (most recent call last):
  File "C:\Users\PROGRAMADOR\AppData\Local\Programs\Python\Python312\Lib\site-packages\flask\app.py", line 1473, in wsgi_app
    response = self.full_dispatch_request()
               ^^^^^^^^^^^^^^^^^^^^^^^^^^^^
  File "C:\Users\PROGRAMADOR\AppData\Local\Programs\Python\Python312\Lib\site-packages\flask\app.py", line 882, in full_dispatch_request
    rv = self.handle_user_exception(e)
         ^^^^^^^^^^^^^^^^^^^^^^^^^^^^^
  File "C:\Users\PROGRAMADOR\AppData\Local\Programs\Python\Python312\Lib\site-packages\flask\app.py", line 880, in full_dispatch_request
    rv = self.dispatch_request()
         ^^^^^^^^^^^^^^^^^^^^^^^
  File "C:\Users\PROGRAMADOR\AppData\Local\Programs\Python\Python312\Lib\site-packages\flask\app.py", line 865, in dispatch_request
    return self.ensure_sync(self.view_functions[rule.endpoint])(**view_args)  # type: ignore[no-any-return]
           ^^^^^^^^^^^^^^^^^^^^^^^^^^^^^^^^^^^^^^^^^^^^^^^^^^^^^^^^^^^^^^^^^
  File "C:\Users\PROGRAMADOR\AppData\Local\Programs\Python\Python312\Lib\site-packages\flask_login\utils.py", line 285, in decorated_view
    return current_app.login_manager.unauthorized()
           ^^^^^^^^^^^^^^^^^^^^^^^^^^^^^^^^^^^^^^^^
  File "C:\Users\PROGRAMADOR\AppData\Local\Programs\Python\Python312\Lib\site-packages\flask_login\login_manager.py", line 187, in unauthorized
    flash(self.login_message, category=self.login_message_category)
  File "C:\Users\PROGRAMADOR\AppData\Local\Programs\Python\Python312\Lib\site-packages\flask\helpers.py", line 323, in flash
    session["_flashes"] = flashes
    ~~~~~~~^^^^^^^^^^^^
  File "C:\Users\PROGRAMADOR\AppData\Local\Programs\Python\Python312\Lib\site-packages\flask\sessions.py", line 102, in _fail
    raise RuntimeError(
RuntimeError: The session is unavailable because no secret key was set.  Set the secret_key on the application to something unique and secret.
2025-07-15 15:55:09,119 INFO: Microblog startup [in C:\Users\PROGRAMADOR\documentos\blog\blog_1\app\__init__.py:43]
2025-07-15 15:55:16,844 ERROR: Exception on / [GET] [in C:\Users\PROGRAMADOR\AppData\Local\Programs\Python\Python312\Lib\site-packages\flask\app.py:838]
Traceback (most recent call last):
  File "C:\Users\PROGRAMADOR\AppData\Local\Programs\Python\Python312\Lib\site-packages\flask\app.py", line 1473, in wsgi_app
    response = self.full_dispatch_request()
               ^^^^^^^^^^^^^^^^^^^^^^^^^^^^
  File "C:\Users\PROGRAMADOR\AppData\Local\Programs\Python\Python312\Lib\site-packages\flask\app.py", line 882, in full_dispatch_request
    rv = self.handle_user_exception(e)
         ^^^^^^^^^^^^^^^^^^^^^^^^^^^^^
  File "C:\Users\PROGRAMADOR\AppData\Local\Programs\Python\Python312\Lib\site-packages\flask\app.py", line 880, in full_dispatch_request
    rv = self.dispatch_request()
         ^^^^^^^^^^^^^^^^^^^^^^^
  File "C:\Users\PROGRAMADOR\AppData\Local\Programs\Python\Python312\Lib\site-packages\flask\app.py", line 865, in dispatch_request
    return self.ensure_sync(self.view_functions[rule.endpoint])(**view_args)  # type: ignore[no-any-return]
           ^^^^^^^^^^^^^^^^^^^^^^^^^^^^^^^^^^^^^^^^^^^^^^^^^^^^^^^^^^^^^^^^^
  File "C:\Users\PROGRAMADOR\AppData\Local\Programs\Python\Python312\Lib\site-packages\flask_login\utils.py", line 290, in decorated_view
    return current_app.ensure_sync(func)(*args, **kwargs)
           ^^^^^^^^^^^^^^^^^^^^^^^^^^^^^^^^^^^^^^^^^^^^^^
  File "C:\Users\PROGRAMADOR\documentos\blog\blog_1\app\routes.py", line 32, in index
    return render_template('index.html', title='Home', posts=posts)
           ^^^^^^^^^^^^^^^^^^^^^^^^^^^^^^^^^^^^^^^^^^^^^^^^^^^^^^^^
  File "C:\Users\PROGRAMADOR\AppData\Local\Programs\Python\Python312\Lib\site-packages\flask\templating.py", line 150, in render_template
    return _render(app, template, context)
           ^^^^^^^^^^^^^^^^^^^^^^^^^^^^^^^
  File "C:\Users\PROGRAMADOR\AppData\Local\Programs\Python\Python312\Lib\site-packages\flask\templating.py", line 131, in _render
    rv = template.render(context)
         ^^^^^^^^^^^^^^^^^^^^^^^^
  File "C:\Users\PROGRAMADOR\AppData\Local\Programs\Python\Python312\Lib\site-packages\jinja2\environment.py", line 1304, in render
    self.environment.handle_exception()
  File "C:\Users\PROGRAMADOR\AppData\Local\Programs\Python\Python312\Lib\site-packages\jinja2\environment.py", line 939, in handle_exception
    raise rewrite_traceback_stack(source=source)
  File "C:\Users\PROGRAMADOR\documentos\blog\blog_1\app\templates\index.html", line 1, in top-level template code
    {% extends "base.html" %}
  File "C:\Users\PROGRAMADOR\documentos\blog\blog_1\app\templates\base.html", line 31, in top-level template code
    {% block content %}{% endblock %}
    ^^^^^^^^^^^^^^^^^^^^^^^^^
  File "C:\Users\PROGRAMADOR\documentos\blog\blog_1\app\templates\index.html", line 4, in block 'content'
    <h1>Hi, {{ user.username }}!</h1>
    ^^^^^^^^^^^^^^^^^^^^^^^^^
  File "C:\Users\PROGRAMADOR\AppData\Local\Programs\Python\Python312\Lib\site-packages\jinja2\environment.py", line 487, in getattr
    return getattr(obj, attribute)
           ^^^^^^^^^^^^^^^^^^^^^^^
jinja2.exceptions.UndefinedError: 'user' is undefined
2025-07-15 15:56:50,330 INFO: Microblog startup [in C:\Users\PROGRAMADOR\documentos\blog\blog_1\app\__init__.py:43]
2025-07-17 15:29:13,165 INFO: Microblog startup [in C:\Users\REDP\Desktop\blogpqnohagonada\blog_1\app\__init__.py:43]
2025-07-17 15:43:29,670 INFO: Microblog startup [in C:\Users\REDP\Desktop\blogpqnohagonada\blog_1\app\__init__.py:43]
2025-07-17 15:43:46,423 INFO: Microblog startup [in C:\Users\REDP\Desktop\blogpqnohagonada\blog_1\app\__init__.py:43]
=======
2025-07-17 15:44:00,757 ERROR: Exception on /register [POST] [in C:\Users\ESTUDIANTE\AppData\Local\Programs\Python\Python313\Lib\site-packages\flask\app.py:875]
Traceback (most recent call last):
  File "C:\Users\ESTUDIANTE\AppData\Local\Programs\Python\Python313\Lib\site-packages\sqlalchemy\engine\base.py", line 1963, in _exec_single_context
    self.dialect.do_execute(
    ~~~~~~~~~~~~~~~~~~~~~~~^
        cursor, str_statement, effective_parameters, context
        ^^^^^^^^^^^^^^^^^^^^^^^^^^^^^^^^^^^^^^^^^^^^^^^^^^^^
    )
    ^
  File "C:\Users\ESTUDIANTE\AppData\Local\Programs\Python\Python313\Lib\site-packages\sqlalchemy\engine\default.py", line 943, in do_execute
    cursor.execute(statement, parameters)
    ~~~~~~~~~~~~~~^^^^^^^^^^^^^^^^^^^^^^^
sqlite3.OperationalError: no such column: user.about_me

The above exception was the direct cause of the following exception:

Traceback (most recent call last):
  File "C:\Users\ESTUDIANTE\AppData\Local\Programs\Python\Python313\Lib\site-packages\flask\app.py", line 1511, in wsgi_app
    response = self.full_dispatch_request()
  File "C:\Users\ESTUDIANTE\AppData\Local\Programs\Python\Python313\Lib\site-packages\flask\app.py", line 919, in full_dispatch_request
    rv = self.handle_user_exception(e)
  File "C:\Users\ESTUDIANTE\AppData\Local\Programs\Python\Python313\Lib\site-packages\flask\app.py", line 917, in full_dispatch_request
    rv = self.dispatch_request()
  File "C:\Users\ESTUDIANTE\AppData\Local\Programs\Python\Python313\Lib\site-packages\flask\app.py", line 902, in dispatch_request
    return self.ensure_sync(self.view_functions[rule.endpoint])(**view_args)  # type: ignore[no-any-return]
           ~~~~~~~~~~~~~~~~~~~~~~~~~~~~~~~~~~~~~~~~~~~~~~~~~~~~^^^^^^^^^^^^^
  File "C:\Users\ESTUDIANTE\Desktop\blogporquenohagonada\blog_1\app\routes.py", line 55, in register
    if form.validate_on_submit():
       ~~~~~~~~~~~~~~~~~~~~~~~^^
  File "C:\Users\ESTUDIANTE\AppData\Local\Programs\Python\Python313\Lib\site-packages\flask_wtf\form.py", line 86, in validate_on_submit
    return self.is_submitted() and self.validate(extra_validators=extra_validators)
                                   ~~~~~~~~~~~~~^^^^^^^^^^^^^^^^^^^^^^^^^^^^^^^^^^^
  File "C:\Users\ESTUDIANTE\AppData\Local\Programs\Python\Python313\Lib\site-packages\wtforms\form.py", line 330, in validate
    return super().validate(extra)
           ~~~~~~~~~~~~~~~~^^^^^^^
  File "C:\Users\ESTUDIANTE\AppData\Local\Programs\Python\Python313\Lib\site-packages\wtforms\form.py", line 147, in validate
    if not field.validate(self, extra):
           ~~~~~~~~~~~~~~^^^^^^^^^^^^^
  File "C:\Users\ESTUDIANTE\AppData\Local\Programs\Python\Python313\Lib\site-packages\wtforms\fields\core.py", line 234, in validate
    stop_validation = self._run_validation_chain(form, chain)
  File "C:\Users\ESTUDIANTE\AppData\Local\Programs\Python\Python313\Lib\site-packages\wtforms\fields\core.py", line 254, in _run_validation_chain
    validator(form, self)
    ~~~~~~~~~^^^^^^^^^^^^
  File "C:\Users\ESTUDIANTE\Desktop\blogporquenohagonada\blog_1\app\forms.py", line 27, in validate_username
    user = db.session.scalar(sa.select(User).where(
        User.username == username.data))
  File "C:\Users\ESTUDIANTE\AppData\Local\Programs\Python\Python313\Lib\site-packages\sqlalchemy\orm\scoping.py", line 1840, in scalar
    return self._proxied.scalar(
           ~~~~~~~~~~~~~~~~~~~~^
        statement,
        ^^^^^^^^^^
    ...<3 lines>...
        **kw,
        ^^^^^
    )
    ^
  File "C:\Users\ESTUDIANTE\AppData\Local\Programs\Python\Python313\Lib\site-packages\sqlalchemy\orm\session.py", line 2413, in scalar
    return self._execute_internal(
           ~~~~~~~~~~~~~~~~~~~~~~^
        statement,
        ^^^^^^^^^^
    ...<4 lines>...
        **kw,
        ^^^^^
    )
    ^
  File "C:\Users\ESTUDIANTE\AppData\Local\Programs\Python\Python313\Lib\site-packages\sqlalchemy\orm\session.py", line 2251, in _execute_internal
    result: Result[Any] = compile_state_cls.orm_execute_statement(
                          ~~~~~~~~~~~~~~~~~~~~~~~~~~~~~~~~~~~~~~~^
        self,
        ^^^^^
    ...<4 lines>...
        conn,
        ^^^^^
    )
    ^
  File "C:\Users\ESTUDIANTE\AppData\Local\Programs\Python\Python313\Lib\site-packages\sqlalchemy\orm\context.py", line 306, in orm_execute_statement
    result = conn.execute(
        statement, params or {}, execution_options=execution_options
    )
  File "C:\Users\ESTUDIANTE\AppData\Local\Programs\Python\Python313\Lib\site-packages\sqlalchemy\engine\base.py", line 1415, in execute
    return meth(
        self,
        distilled_parameters,
        execution_options or NO_OPTIONS,
    )
  File "C:\Users\ESTUDIANTE\AppData\Local\Programs\Python\Python313\Lib\site-packages\sqlalchemy\sql\elements.py", line 523, in _execute_on_connection
    return connection._execute_clauseelement(
           ~~~~~~~~~~~~~~~~~~~~~~~~~~~~~~~~~^
        self, distilled_params, execution_options
        ^^^^^^^^^^^^^^^^^^^^^^^^^^^^^^^^^^^^^^^^^
    )
    ^
  File "C:\Users\ESTUDIANTE\AppData\Local\Programs\Python\Python313\Lib\site-packages\sqlalchemy\engine\base.py", line 1637, in _execute_clauseelement
    ret = self._execute_context(
        dialect,
    ...<8 lines>...
        cache_hit=cache_hit,
    )
  File "C:\Users\ESTUDIANTE\AppData\Local\Programs\Python\Python313\Lib\site-packages\sqlalchemy\engine\base.py", line 1842, in _execute_context
    return self._exec_single_context(
           ~~~~~~~~~~~~~~~~~~~~~~~~~^
        dialect, context, statement, parameters
        ^^^^^^^^^^^^^^^^^^^^^^^^^^^^^^^^^^^^^^^
    )
    ^
  File "C:\Users\ESTUDIANTE\AppData\Local\Programs\Python\Python313\Lib\site-packages\sqlalchemy\engine\base.py", line 1982, in _exec_single_context
    self._handle_dbapi_exception(
    ~~~~~~~~~~~~~~~~~~~~~~~~~~~~^
        e, str_statement, effective_parameters, cursor, context
        ^^^^^^^^^^^^^^^^^^^^^^^^^^^^^^^^^^^^^^^^^^^^^^^^^^^^^^^
    )
    ^
  File "C:\Users\ESTUDIANTE\AppData\Local\Programs\Python\Python313\Lib\site-packages\sqlalchemy\engine\base.py", line 2351, in _handle_dbapi_exception
    raise sqlalchemy_exception.with_traceback(exc_info[2]) from e
  File "C:\Users\ESTUDIANTE\AppData\Local\Programs\Python\Python313\Lib\site-packages\sqlalchemy\engine\base.py", line 1963, in _exec_single_context
    self.dialect.do_execute(
    ~~~~~~~~~~~~~~~~~~~~~~~^
        cursor, str_statement, effective_parameters, context
        ^^^^^^^^^^^^^^^^^^^^^^^^^^^^^^^^^^^^^^^^^^^^^^^^^^^^
    )
    ^
  File "C:\Users\ESTUDIANTE\AppData\Local\Programs\Python\Python313\Lib\site-packages\sqlalchemy\engine\default.py", line 943, in do_execute
    cursor.execute(statement, parameters)
    ~~~~~~~~~~~~~~^^^^^^^^^^^^^^^^^^^^^^^
sqlalchemy.exc.OperationalError: (sqlite3.OperationalError) no such column: user.about_me
[SQL: SELECT user.id, user.username, user.email, user.password_hash, user.about_me, user.last_seen 
FROM user 
WHERE user.username = ?]
[parameters: ('popo',)]
(Background on this error at: https://sqlalche.me/e/20/e3q8)
2025-07-17 15:46:12,669 INFO: Microblog startup [in C:\Users\ESTUDIANTE\Desktop\blogporquenohagonada\blog_1\app\__init__.py:43]
2025-07-17 15:46:34,271 INFO: Microblog startup [in C:\Users\ESTUDIANTE\Desktop\blogporquenohagonada\blog_1\app\__init__.py:43]
2025-07-17 15:47:56,926 INFO: Microblog startup [in C:\Users\ESTUDIANTE\Desktop\blogporquenohagonada\blog_1\app\__init__.py:43]
>>>>>>> 61a42826af467f946fefd7b703bfabaebf4bf721
